Traceback (most recent call last):
  File "/Users/anhpham/Library/Python/3.9/lib/python/site-packages/jupyter_cache/executors/utils.py", line 51, in single_nb_execution
    executenb(
  File "/Users/anhpham/Library/Python/3.9/lib/python/site-packages/nbclient/client.py", line 1204, in execute
    return NotebookClient(nb=nb, resources=resources, km=km, **kwargs).execute()
  File "/Users/anhpham/Library/Python/3.9/lib/python/site-packages/nbclient/util.py", line 84, in wrapped
    return just_run(coro(*args, **kwargs))
  File "/Users/anhpham/Library/Python/3.9/lib/python/site-packages/nbclient/util.py", line 62, in just_run
    return loop.run_until_complete(coro)
  File "/Library/Developer/CommandLineTools/Library/Frameworks/Python3.framework/Versions/3.9/lib/python3.9/asyncio/base_events.py", line 642, in run_until_complete
    return future.result()
  File "/Users/anhpham/Library/Python/3.9/lib/python/site-packages/nbclient/client.py", line 663, in async_execute
    await self.async_execute_cell(
  File "/Users/anhpham/Library/Python/3.9/lib/python/site-packages/nbclient/client.py", line 965, in async_execute_cell
    await self._check_raise_for_error(cell, cell_index, exec_reply)
  File "/Users/anhpham/Library/Python/3.9/lib/python/site-packages/nbclient/client.py", line 862, in _check_raise_for_error
    raise CellExecutionError.from_cell_and_msg(cell, exec_reply_content)
nbclient.exceptions.CellExecutionError: An error occurred while executing the following cell:
------------------
# Create Datafram with only african-americans
raw_data = load_raw_df()
df_black = raw_data.loc[raw_data['race'].isin(["African-American"])]
df_black.shape
------------------

[0;31m---------------------------------------------------------------------------[0m
[0;31mNameError[0m                                 Traceback (most recent call last)
Cell [0;32mIn [20], line 2[0m
[1;32m      1[0m [38;5;66;03m# Create Datafram with only african-americans[39;00m
[0;32m----> 2[0m raw_data [38;5;241m=[39m load_raw_df()
[1;32m      3[0m df_black [38;5;241m=[39m raw_data[38;5;241m.[39mloc[raw_data[[38;5;124m'[39m[38;5;124mrace[39m[38;5;124m'[39m][38;5;241m.[39misin([[38;5;124m"[39m[38;5;124mAfrican-American[39m[38;5;124m"[39m])]
[1;32m      4[0m df_black[38;5;241m.[39mshape

[0;31mNameError[0m: name 'load_raw_df' is not defined
NameError: name 'load_raw_df' is not defined

