Traceback (most recent call last):
  File "/Users/anhpham/Library/Python/3.9/lib/python/site-packages/jupyter_cache/executors/utils.py", line 51, in single_nb_execution
    executenb(
  File "/Users/anhpham/Library/Python/3.9/lib/python/site-packages/nbclient/client.py", line 1204, in execute
    return NotebookClient(nb=nb, resources=resources, km=km, **kwargs).execute()
  File "/Users/anhpham/Library/Python/3.9/lib/python/site-packages/nbclient/util.py", line 84, in wrapped
    return just_run(coro(*args, **kwargs))
  File "/Users/anhpham/Library/Python/3.9/lib/python/site-packages/nbclient/util.py", line 62, in just_run
    return loop.run_until_complete(coro)
  File "/Library/Developer/CommandLineTools/Library/Frameworks/Python3.framework/Versions/3.9/lib/python3.9/asyncio/base_events.py", line 642, in run_until_complete
    return future.result()
  File "/Users/anhpham/Library/Python/3.9/lib/python/site-packages/nbclient/client.py", line 663, in async_execute
    await self.async_execute_cell(
  File "/Users/anhpham/Library/Python/3.9/lib/python/site-packages/nbclient/client.py", line 965, in async_execute_cell
    await self._check_raise_for_error(cell, cell_index, exec_reply)
  File "/Users/anhpham/Library/Python/3.9/lib/python/site-packages/nbclient/client.py", line 862, in _check_raise_for_error
    raise CellExecutionError.from_cell_and_msg(cell, exec_reply_content)
nbclient.exceptions.CellExecutionError: An error occurred while executing the following cell:
------------------
df_new = X_test
df_new['y_test'] = y_test
df_new['y_pred'] = y_pred

df_whites = df_new.loc[df['race'] == "Caucasian"]
df_blacks = df_new.loc[df['race'] == "African-American"]
------------------

[0;31m---------------------------------------------------------------------------[0m
[0;31mNameError[0m                                 Traceback (most recent call last)
Cell [0;32mIn [28], line 3[0m
[1;32m      1[0m df_new [38;5;241m=[39m X_test
[1;32m      2[0m df_new[[38;5;124m'[39m[38;5;124my_test[39m[38;5;124m'[39m] [38;5;241m=[39m y_test
[0;32m----> 3[0m df_new[[38;5;124m'[39m[38;5;124my_pred[39m[38;5;124m'[39m] [38;5;241m=[39m y_pred
[1;32m      5[0m df_whites [38;5;241m=[39m df_new[38;5;241m.[39mloc[df[[38;5;124m'[39m[38;5;124mrace[39m[38;5;124m'[39m] [38;5;241m==[39m [38;5;124m"[39m[38;5;124mCaucasian[39m[38;5;124m"[39m]
[1;32m      6[0m df_blacks [38;5;241m=[39m df_new[38;5;241m.[39mloc[df[[38;5;124m'[39m[38;5;124mrace[39m[38;5;124m'[39m] [38;5;241m==[39m [38;5;124m"[39m[38;5;124mAfrican-American[39m[38;5;124m"[39m]

[0;31mNameError[0m: name 'y_pred' is not defined
NameError: name 'y_pred' is not defined

